Workbook
Name NativeTimeline_Order_Date: #N/A
Name Slicer_Loyalty_Card: #N/A
Name Slicer_Roast_Type_Name: #N/A
Name Slicer_Size: #N/A

Sheet Total Sales
A3: Sum of Sales | C3: Coffee Type
A4: Years (Order Date) | B4: Months (Order Date) | C4: Ara | D4: Exc | E4: Lib | F4: Rob | G4: Grand Total
A5: 2019 | B5: Jan | C5: 186.855 | D5: 305.97 | E5: 213.16 | F5: 123 | G5: 828.985
B6: Feb | C6: 251.965 | D6: 129.46 | E6: 434.04 | F6: 171.94 | G6: 987.405
B7: Mar | C7: 224.945 | D7: 349.12 | E7: 321.04 | F7: 126.035 | G7: 1021.14
B8: Apr | C8: 307.12 | D8: 681.075 | E8: 533.705 | F8: 158.85 | G8: 1680.75
B9: May | C9: 53.665 | D9: 83.025 | E9: 193.835 | F9: 68.04 | G9: 398.565
B10: Jun | C10: 163.02 | D10: 678.36 | E10: 171.045 | F10: 372.255 | G10: 1384.68
B11: Jul | C11: 345.02 | D11: 273.87 | E11: 184.13 | F11: 201.115 | G11: 1004.135
B12: Aug | C12: 334.89 | D12: 70.95 | E12: 134.23 | F12: 166.275 | G12: 706.345
B13: Sep | C13: 178.71 | D13: 166.1 | E13: 439.31 | F13: 492.9 | G13: 1277.02
B14: Oct | C14: 301.985 | D14: 153.765 | E14: 215.555 | F14: 213.665 | G14: 884.97
B15: Nov | C15: 312.835 | D15: 63.25 | E15: 350.895 | F15: 96.405 | G15: 823.385
B16: Dec | C16: 265.62 | D16: 526.515 | E16: 187.06 | F16: 210.59 | G16: 1189.785
A17: 2020 | B17: Jan | C17: 47.25 | D17: 65.805 | E17: 274.675 | F17: 179.22 | G17: 566.95
B18: Feb | C18: 745.45 | D18: 428.885 | E18: 194.175 | F18: 429.83 | G18: 1798.34
B19: Mar | C19: 130.47 | D19: 271.485 | E19: 281.205 | F19: 231.63 | G19: 914.79
B20: Apr | C20: 27 | D20: 347.26 | E20: 147.51 | F20: 240.04 | G20: 761.81
B21: May | C21: 255.115 | D21: 541.73 | E21: 83.43 | F21: 59.08 | G21: 939.355
B22: Jun | C22: 584.79 | D22: 357.43 | E22: 355.34 | F22: 140.88 | G22: 1438.44
B23: Jul | C23: 430.62 | D23: 227.425 | E23: 236.315 | F23: 414.585 | G23: 1308.945
B24: Aug | C24: 22.5 | D24: 77.72 | E24: 60.5 | F24: 139.68 | G24: 300.4
B25: Sep | C25: 126.15 | D25: 195.11 | E25: 89.13 | F25: 302.66 | G25: 713.05
B26: Oct | C26: 376.03 | D26: 523.24 | E26: 440.965 | F26: 174.47 | G26: 1514.705
B27: Nov | C27: 515.18 | D27: 142.56 | E27: 347.04 | F27: 104.085 | G27: 1108.865
B28: Dec | C28: 95.86 | D28: 484.76 | E28: 94.17 | F28: 77.105 | G28: 751.895
A29: 2021 | B29: Jan | C29: 258.345 | D29: 139.625 | E29: 279.52 | F29: 160.195 | G29: 837.685
B30: Feb | C30: 342.2 | D30: 284.25 | E30: 251.83 | F30: 80.55 | G30: 958.83
B31: Mar | C31: 418.305 | D31: 468.125 | E31: 405.055 | F31: 253.155 | G31: 1544.64
B32: Apr | C32: 102.33 | D32: 242.14 | E32: 554.875 | F32: 106.24 | G32: 1005.585
B33: May | C33: 234.72 | D33: 133.08 | E33: 267.2 | F33: 272.69 | G33: 907.69
B34: Jun | C34: 430.39 | D34: 136.205 | E34: 209.6 | F34: 88.335 | G34: 864.53
B35: Jul | C35: 109.005 | D35: 393.575 | E35: 61.035 | F35: 199.49 | G35: 763.105
B36: Aug | C36: 287.525 | D36: 288.67 | E36: 125.58 | F36: 374.135 | G36: 1075.91
B37: Sep | C37: 840.93 | D37: 409.875 | E37: 171.33 | F37: 221.44 | G37: 1643.575
B38: Oct | C38: 299.07 | D38: 260.325 | E38: 584.64 | F38: 256.365 | G38: 1400.4
B39: Nov | C39: 323.325 | D39: 565.57 | E39: 537.81 | F39: 189.475 | G39: 1616.18
B40: Dec | C40: 399.485 | D40: 148.2 | E40: 388.22 | F40: 212.075 | G40: 1147.98
A41: 2022 | B41: Jan | C41: 112.695 | D41: 166.32 | E41: 843.715 | F41: 146.685 | G41: 1269.415
B42: Feb | C42: 114.88 | D42: 133.815 | E42: 91.175 | F42: 53.76 | G42: 393.63
...

Sheet CountryBarChart
A3: Country | B3: Sum of Sales
A4: United Kingdom | B4: 2798.505
A5: Ireland | B5: 6696.865
A6: United States | B6: 35638.885

Sheet Top5Customers
A3: Customer Name | B3: Sum of Sales
A4: Don Flintiff | B4: 278.01
A5: Nealson Cuttler | B5: 281.675
A6: Terri Farra | B6: 289.11
A7: Brenn Dundredge | B7: 307.045
A8: Allis Wilmore | B8: 317.07

Sheet DashBoard

Sheet orders
A1: Order ID | B1: Order Date | C1: Customer ID | D1: Product ID | E1: Quantity | F1: Customer Name | G1: Email | H1: Country | I1: Coffee Type | J1: Roast Type | K1: Size | L1: Unit Price | M1: Sales | N1: Coffee Type Name | O1: Roast Type Name | P1: Loyalty Card
A2: QEV-37451-860 | B2: 43713 | C2: 17670-51384-MA | D2: R-M-1 | E2: 2 | F2: {=_xlfn.XLOOKUP(C2, customers!$A$1:A1001, customers!$B$1:B1001, 0)} -> Aloisia Allner | G2: =IF(_xlfn.XLOOKUP(C2, customers!A1:A1001, customers!C1:C1001, 0)=0, "", _xlfn.XLOOKUP(C2, customers!A1:A1001, customers!C1:C1001, 0)) -> aallner0@lulu.com | H2: {=_xlfn.XLOOKUP(C2, customers!$A$1:A1001, customers!$G$1:G1001,, 0)} -> United States | I2: {=_xlfn.XLOOKUP(orders!D2, products!$A$1:A49, products!$B$1:B49, 0)} -> Rob | J2: {=_xlfn.XLOOKUP(D2, products!$A$1:A49, products!$C$1:C49, 0)} -> M | K2: {=_xlfn.XLOOKUP(D2, products!$A$1:A49, products!$D$1:D49, 0)} -> 1 | L2: {=_xlfn.XLOOKUP(D2, products!$A$1:A49, products!$E$1:E49)} -> 9.95 | M2: =L2*E2 -> 19.9 | N2: =IF(I2="Rob", "Robusta", IF(I2="Exc", "Excelsa", IF(I2="Ara", "Arabica", IF(I2="Lib", "Liberica", "")))) -> Robusta | O2: {=_xlfn.IFS(J2="M", "Medium", J2="L", "Light", J2="D", "Dark")} -> Medium | P2: =_xlfn.XLOOKUP(Orders[[#This Row],[Customer ID]], customers!$A$2:$A$1001, customers!$I$2:$I$1001, 0) -> Yes
A3: QEV-37451-860 | B3: 43713 | C3: 17670-51384-MA | D3: E-M-0.5 | E3: 5 | F3: {=_xlfn.XLOOKUP(C3, customers!$A$1:A1002, customers!$B$1:B1002, 0)} -> Aloisia Allner | G3: =IF(_xlfn.XLOOKUP(C3, customers!A2:A1002, customers!C2:C1002, 0)=0, "", _xlfn.XLOOKUP(C3, customers!A2:A1002, customers!C2:C1002, 0)) -> aallner0@lulu.com | H3: {=_xlfn.XLOOKUP(C3, customers!$A$1:A1002, customers!$G$1:G1002,, 0)} -> United States | I3: {=_xlfn.XLOOKUP(orders!D3, products!$A$1:A50, products!$B$1:B50, 0)} -> Exc | J3: {=_xlfn.XLOOKUP(D3, products!$A$1:A50, products!$C$1:C50, 0)} -> M | K3: {=_xlfn.XLOOKUP(D3, products!$A$1:A50, products!$D$1:D50, 0)} -> 0.5 | L3: {=_xlfn.XLOOKUP(D3, products!$A$1:A50, products!$E$1:E50)} -> 8.25 | M3: =L3*E3 -> 41.25 | N3: =IF(I3="Rob", "Robusta", IF(I3="Exc", "Excelsa", IF(I3="Ara", "Arabica", IF(I3="Lib", "Liberica", "")))) -> Excelsa | O3: {=_xlfn.IFS(J3="M", "Medium", J3="L", "Light", J3="D", "Dark")} -> Medium | P3: =_xlfn.XLOOKUP(Orders[[#This Row],[Customer ID]], customers!$A$2:$A$1001, customers!$I$2:$I$1001, 0) -> Yes
A4: FAA-43335-268 | B4: 44364 | C4: 21125-22134-PX | D4: A-L-1 | E4: 1 | F4: {=_xlfn.XLOOKUP(C4, customers!$A$1:A1003, customers!$B$1:B1003, 0)} -> Jami Redholes | G4: =IF(_xlfn.XLOOKUP(C4, customers!A3:A1003, customers!C3:C1003, 0)=0, "", _xlfn.XLOOKUP(C4, customers!A3:A1003, customers!C3:C1003, 0)) -> jredholes2@tmall.com | H4: {=_xlfn.XLOOKUP(C4, customers!$A$1:A1003, customers!$G$1:G1003,, 0)} -> United States | I4: {=_xlfn.XLOOKUP(orders!D4, products!$A$1:A51, products!$B$1:B51, 0)} -> Ara | J4: {=_xlfn.XLOOKUP(D4, products!$A$1:A51, products!$C$1:C51, 0)} -> L | K4: {=_xlfn.XLOOKUP(D4, products!$A$1:A51, products!$D$1:D51, 0)} -> 1 | L4: {=_xlfn.XLOOKUP(D4, products!$A$1:A51, products!$E$1:E51)} -> 12.95 | M4: =L4*E4 -> 12.95 | N4: =IF(I4="Rob", "Robusta", IF(I4="Exc", "Excelsa", IF(I4="Ara", "Arabica", IF(I4="Lib", "Liberica", "")))) -> Arabica | O4: {=_xlfn.IFS(J4="M", "Medium", J4="L", "Light", J4="D", "Dark")} -> Light | P4: =_xlfn.XLOOKUP(Orders[[#This Row],[Customer ID]], customers!$A$2:$A$1001, customers!$I$2:$I$1001, 0) -> Yes
A5: KAC-83089-793 | B5: 44392 | C5: 23806-46781-OU | D5: E-M-1 | E5: 2 | F5: {=_xlfn.XLOOKUP(C5, customers!$A$1:A1004, customers!$B$1:B1004, 0)} -> Christoffer O' Shea | G5: =IF(_xlfn.XLOOKUP(C5, customers!A4:A1004, customers!C4:C1004, 0)=0, "", _xlfn.XLOOKUP(C5, customers!A4:A1004, customers!C4:C1004, 0)) | H5: {=_xlfn.XLOOKUP(C5, customers!$A$1:A1004, customers!$G$1:G1004,, 0)} -> Ireland | I5: {=_xlfn.XLOOKUP(orders!D5, products!$A$1:A52, products!$B$1:B52, 0)} -> Exc | J5: {=_xlfn.XLOOKUP(D5, products!$A$1:A52, products!$C$1:C52, 0)} -> M | K5: {=_xlfn.XLOOKUP(D5, products!$A$1:A52, products!$D$1:D52, 0)} -> 1 | L5: {=_xlfn.XLOOKUP(D5, products!$A$1:A52, products!$E$1:E52)} -> 13.75 | M5: =L5*E5 -> 27.5 | N5: =IF(I5="Rob", "Robusta", IF(I5="Exc", "Excelsa", IF(I5="Ara", "Arabica", IF(I5="Lib", "Liberica", "")))) -> Excelsa | O5: {=_xlfn.IFS(J5="M", "Medium", J5="L", "Light", J5="D", "Dark")} -> Medium | P5: =_xlfn.XLOOKUP(Orders[[#This Row],[Customer ID]], customers!$A$2:$A$1001, customers!$I$2:$I$1001, 0) -> No
A6: KAC-83089-793 | B6: 44392 | C6: 23806-46781-OU | D6: R-L-2.5 | E6: 2 | F6: {=_xlfn.XLOOKUP(C6, customers!$A$1:A1005, customers!$B$1:B1005, 0)} -> Christoffer O' Shea | G6: =IF(_xlfn.XLOOKUP(C6, customers!A5:A1005, customers!C5:C1005, 0)=0, "", _xlfn.XLOOKUP(C6, customers!A5:A1005, customers!C5:C1005, 0)) | H6: {=_xlfn.XLOOKUP(C6, customers!$A$1:A1005, customers!$G$1:G1005,, 0)} -> Ireland | I6: {=_xlfn.XLOOKUP(orders!D6, products!$A$1:A53, products!$B$1:B53, 0)} -> Rob | J6: {=_xlfn.XLOOKUP(D6, products!$A$1:A53, products!$C$1:C53, 0)} -> L | K6: {=_xlfn.XLOOKUP(D6, products!$A$1:A53, products!$D$1:D53, 0)} -> 2.5 | L6: {=_xlfn.XLOOKUP(D6, products!$A$1:A53, products!$E$1:E53)} -> 27.485 | M6: =L6*E6 -> 54.97 | N6: =IF(I6="Rob", "Robusta", IF(I6="Exc", "Excelsa", IF(I6="Ara", "Arabica", IF(I6="Lib", "Liberica", "")))) -> Robusta | O6: {=_xlfn.IFS(J6="M", "Medium", J6="L", "Light", J6="D", "Dark")} -> Light | P6: =_xlfn.XLOOKUP(Orders[[#This Row],[Customer ID]], customers!$A$2:$A$1001, customers!$I$2:$I$1001, 0) -> No
A7: CVP-18956-553 | B7: 44412 | C7: 86561-91660-RB | D7: L-D-1 | E7: 3 | F7: {=_xlfn.XLOOKUP(C7, customers!$A$1:A1006, customers!$B$1:B1006, 0)} -> Beryle Cottier | G7: =IF(_xlfn.XLOOKUP(C7, customers!A6:A1006, customers!C6:C1006, 0)=0, "", _xlfn.XLOOKUP(C7, customers!A6:A1006, customers!C6:C1006, 0)) | H7: {=_xlfn.XLOOKUP(C7, customers!$A$1:A1006, customers!$G$1:G1006,, 0)} -> United States | I7: {=_xlfn.XLOOKUP(orders!D7, products!$A$1:A54, products!$B$1:B54, 0)} -> Lib | J7: {=_xlfn.XLOOKUP(D7, products!$A$1:A54, products!$C$1:C54, 0)} -> D | K7: {=_xlfn.XLOOKUP(D7, products!$A$1:A54, products!$D$1:D54, 0)} -> 1 | L7: {=_xlfn.XLOOKUP(D7, products!$A$1:A54, products!$E$1:E54)} -> 12.95 | M7: =L7*E7 -> 38.85 | N7: =IF(I7="Rob", "Robusta", IF(I7="Exc", "Excelsa", IF(I7="Ara", "Arabica", IF(I7="Lib", "Liberica", "")))) -> Liberica | O7: {=_xlfn.IFS(J7="M", "Medium", J7="L", "Light", J7="D", "Dark")} -> Dark | P7: =_xlfn.XLOOKUP(Orders[[#This Row],[Customer ID]], customers!$A$2:$A$1001, customers!$I$2:$I$1001, 0) -> No
A8: IPP-31994-879 | B8: 44582 | C8: 65223-29612-CB | D8: E-D-0.5 | E8: 3 | F8: {=_xlfn.XLOOKUP(C8, customers!$A$1:A1007, customers!$B$1:B1007, 0)} -> Shaylynn Lobe | G8: =IF(_xlfn.XLOOKUP(C8, customers!A7:A1007, customers!C7:C1007, 0)=0, "", _xlfn.XLOOKUP(C8, customers!A7:A1007, customers!C7:C1007, 0)) -> slobe6@nifty.com | H8: {=_xlfn.XLOOKUP(C8, customers!$A$1:A1007, customers!$G$1:G1007,, 0)} -> United States | I8: {=_xlfn.XLOOKUP(orders!D8, products!$A$1:A55, products!$B$1:B55, 0)} -> Exc | J8: {=_xlfn.XLOOKUP(D8, products!$A$1:A55, products!$C$1:C55, 0)} -> D | K8: {=_xlfn.XLOOKUP(D8, products!$A$1:A55, products!$D$1:D55, 0)} -> 0.5 | L8: {=_xlfn.XLOOKUP(D8, products!$A$1:A55, products!$E$1:E55)} -> 7.29 | M8: =L8*E8 -> 21.87 | N8: =IF(I8="Rob", "Robusta", IF(I8="Exc", "Excelsa", IF(I8="Ara", "Arabica", IF(I8="Lib", "Liberica", "")))) -> Excelsa | O8: {=_xlfn.IFS(J8="M", "Medium", J8="L", "Light", J8="D", "Dark")} -> Dark | P8: =_xlfn.XLOOKUP(Orders[[#This Row],[Customer ID]], customers!$A$2:$A$1001, customers!$I$2:$I$1001, 0) -> Yes
A9: SNZ-65340-705 | B9: 44701 | C9: 21134-81676-FR | D9: L-L-0.2 | E9: 1 | F9: {=_xlfn.XLOOKUP(C9, customers!$A$1:A1008, customers!$B$1:B1008, 0)} -> Melvin Wharfe | G9: =IF(_xlfn.XLOOKUP(C9, customers!A8:A1008, customers!C8:C1008, 0)=0, "", _xlfn.XLOOKUP(C9, customers!A8:A1008, customers!C8:C1008, 0)) | H9: {=_xlfn.XLOOKUP(C9, customers!$A$1:A1008, customers!$G$1:G1008,, 0)} -> Ireland | I9: {=_xlfn.XLOOKUP(orders!D9, products!$A$1:A56, products!$B$1:B56, 0)} -> Lib | J9: {=_xlfn.XLOOKUP(D9, products!$A$1:A56, products!$C$1:C56, 0)} -> L | K9: {=_xlfn.XLOOKUP(D9, products!$A$1:A56, products!$D$1:D56, 0)} -> 0.2 | L9: {=_xlfn.XLOOKUP(D9, products!$A$1:A56, products!$E$1:E56)} -> 4.755 | M9: =L9*E9 -> 4.755 | N9: =IF(I9="Rob", "Robusta", IF(I9="Exc", "Excelsa", IF(I9="Ara", "Arabica", IF(I9="Lib", "Liberica", "")))) -> Liberica | O9: {=_xlfn.IFS(J9="M", "Medium", J9="L", "Light", J9="D", "Dark")} -> Light | P9: =_xlfn.XLOOKUP(Orders[[#This Row],[Customer ID]], customers!$A$2:$A$1001, customers!$I$2:$I$1001, 0) -> Yes
A10: EZT-46571-659 | B10: 43467 | C10: 03396-68805-ZC | D10: R-M-0.5 | E10: 3 | F10: {=_xlfn.XLOOKUP(C10, customers!$A$1:A1009, customers!$B$1:B1009, 0)} -> Guthrey Petracci | G10: =IF(_xlfn.XLOOKUP(C10, customers!A9:A1009, customers!C9:C1009, 0)=0, "", _xlfn.XLOOKUP(C10, customers!A9:A1009, customers!C9:C1009, 0)) -> gpetracci8@livejournal.com | H10: {=_xlfn.XLOOKUP(C10, customers!$A$1:A1009, customers!$G$1:G1009,, 0)} -> United States | I10: {=_xlfn.XLOOKUP(orders!D10, products!$A$1:A57, products!$B$1:B57, 0)} -> Rob | J10: {=_xlfn.XLOOKUP(D10, products!$A$1:A57, products!$C$1:C57, 0)} -> M | K10: {=_xlfn.XLOOKUP(D10, products!$A$1:A57, products!$D$1:D57, 0)} -> 0.5 | L10: {=_xlfn.XLOOKUP(D10, products!$A$1:A57, products!$E$1:E57)} -> 5.97 | M10: =L10*E10 -> 17.91 | N10: =IF(I10="Rob", "Robusta", IF(I10="Exc", "Excelsa", IF(I10="Ara", "Arabica", IF(I10="Lib", "Liberica", "")))) -> Robusta | O10: {=_xlfn.IFS(J10="M", "Medium", J10="L", "Light", J10="D", "Dark")} -> Medium | P10: =_xlfn.XLOOKUP(Orders[[#This Row],[Customer ID]], customers!$A$2:$A$1001, customers!$I$2:$I$1001, 0) -> No
A11: NWQ-70061-912 | B11: 43713 | C11: 61021-27840-ZN | D11: R-M-0.5 | E11: 1 | F11: {=_xlfn.XLOOKUP(C11, customers!$A$1:A1010, customers!$B$1:B1010, 0)} -> Rodger Raven | G11: =IF(_xlfn.XLOOKUP(C11, customers!A10:A1010, customers!C10:C1010, 0)=0, "", _xlfn.XLOOKUP(C11, customers!A10:A1010, customers!C10:C1010, 0)) -> rraven9@ed.gov | H11: {=_xlfn.XLOOKUP(C11, customers!$A$1:A1010, customers!$G$1:G1010,, 0)} -> United States | I11: {=_xlfn.XLOOKUP(orders!D11, products!$A$1:A58, products!$B$1:B58, 0)} -> Rob | J11: {=_xlfn.XLOOKUP(D11, products!$A$1:A58, products!$C$1:C58, 0)} -> M | K11: {=_xlfn.XLOOKUP(D11, products!$A$1:A58, products!$D$1:D58, 0)} -> 0.5 | L11: {=_xlfn.XLOOKUP(D11, products!$A$1:A58, products!$E$1:E58)} -> 5.97 | M11: =L11*E11 -> 5.97 | N11: =IF(I11="Rob", "Robusta", IF(I11="Exc", "Excelsa", IF(I11="Ara", "Arabica", IF(I11="Lib", "Liberica", "")))) -> Robusta | O11: {=_xlfn.IFS(J11="M", "Medium", J11="L", "Light", J11="D", "Dark")} -> Medium | P11: =_xlfn.XLOOKUP(Orders[[#This Row],[Customer ID]], customers!$A$2:$A$1001, customers!$I$2:$I$1001, 0) -> No
A12: BKK-47233-845 | B12: 44263 | C12: 76239-90137-UQ | D12: A-D-1 | E12: 4 | F12: {=_xlfn.XLOOKUP(C12, customers!$A$1:A1011, customers!$B$1:B1011, 0)} -> Ferrell Ferber | G12: =IF(_xlfn.XLOOKUP(C12, customers!A11:A1011, customers!C11:C1011, 0)=0, "", _xlfn.XLOOKUP(C12, customers!A11:A1011, customers!C11:C1011, 0)) -> fferbera@businesswire.com | H12: {=_xlfn.XLOOKUP(C12, customers!$A$1:A1011, customers!$G$1:G1011,, 0)} -> United States | I12: {=_xlfn.XLOOKUP(orders!D12, products!$A$1:A59, products!$B$1:B59, 0)} -> Ara | J12: {=_xlfn.XLOOKUP(D12, products!$A$1:A59, products!$C$1:C59, 0)} -> D | K12: {=_xlfn.XLOOKUP(D12, products!$A$1:A59, products!$D$1:D59, 0)} -> 1 | L12: {=_xlfn.XLOOKUP(D12, products!$A$1:A59, products!$E$1:E59)} -> 9.95 | M12: =L12*E12 -> 39.8 | N12: =IF(I12="Rob", "Robusta", IF(I12="Exc", "Excelsa", IF(I12="Ara", "Arabica", IF(I12="Lib", "Liberica", "")))) -> Arabica | O12: {=_xlfn.IFS(J12="M", "Medium", J12="L", "Light", J12="D", "Dark")} -> Dark | P12: =_xlfn.XLOOKUP(Orders[[#This Row],[Customer ID]], customers!$A$2:$A$1001, customers!$I$2:$I$1001, 0) -> No
A13: VQR-01002-970 | B13: 44132 | C13: 49315-21985-BB | D13: E-L-2.5 | E13: 5 | F13: {=_xlfn.XLOOKUP(C13, customers!$A$1:A1012, customers!$B$1:B1012, 0)} -> Duky Phizackerly | G13: =IF(_xlfn.XLOOKUP(C13, customers!A12:A1012, customers!C12:C1012, 0)=0, "", _xlfn.XLOOKUP(C13, customers!A12:A1012, customers!C12:C1012, 0)) -> dphizackerlyb@utexas.edu | H13: {=_xlfn.XLOOKUP(C13, customers!$A$1:A1012, customers!$G$1:G1012,, 0)} -> United States | I13: {=_xlfn.XLOOKUP(orders!D13, products!$A$1:A60, products!$B$1:B60, 0)} -> Exc | J13: {=_xlfn.XLOOKUP(D13, products!$A$1:A60, products!$C$1:C60, 0)} -> L | K13: {=_xlfn.XLOOKUP(D13, products!$A$1:A60, products!$D$1:D60, 0)} -> 2.5 | L13: {=_xlfn.XLOOKUP(D13, products!$A$1:A60, products!$E$1:E60)} -> 34.155 | M13: =L13*E13 -> 170.775 | N13: =IF(I13="Rob", "Robusta", IF(I13="Exc", "Excelsa", IF(I13="Ara", "Arabica", IF(I13="Lib", "Liberica", "")))) -> Excelsa | O13: {=_xlfn.IFS(J13="M", "Medium", J13="L", "Light", J13="D", "Dark")} -> Light | P13: =_xlfn.XLOOKUP(Orders[[#This Row],[Customer ID]], customers!$A$2:$A$1001, customers!$I$2:$I$1001, 0) -> Yes
... A1001: IRV-20769-219 | B1001: 44119 | C1001: 77131-58092-GE | D1001: E-M-0.2 | E1001: 3 | F1001: {=_xlfn.XLOOKUP(C1001, customers!$A$1:A2000, customers!$B$1:B2000, 0)} -> Vidovic Antonelli | G1001: =IF(_xlfn.XLOOKUP(C1001, customers!A1000:A2000, customers!C1000:C2000, 0)=0, "", _xlfn.XLOOKUP(C1001, customers!A1000:A2000, customers!C1000:C2000, 0)) | H1001: {=_xlfn.XLOOKUP(C1001, customers!$A$1:A2000, customers!$G$1:G2000,, 0)} -> United Kingdom | I1001: {=_xlfn.XLOOKUP(orders!D1001, products!$A$1:A1048, products!$B$1:B1048, 0)} -> Exc | J1001: {=_xlfn.XLOOKUP(D1001, products!$A$1:A1048, products!$C$1:C1048, 0)} -> M | K1001: {=_xlfn.XLOOKUP(D1001, products!$A$1:A1048, products!$D$1:D1048, 0)} -> 0.2 | L1001: {=_xlfn.XLOOKUP(D1001, products!$A$1:A1048, products!$E$1:E1048)} -> 4.125 | M1001: =L1001*E1001 -> 12.375 | N1001: =IF(I1001="Rob", "Robusta", IF(I1001="Exc", "Excelsa", IF(I1001="Ara", "Arabica", IF(I1001="Lib", "Liberica", "")))) -> Excelsa | O1001: {=_xlfn.IFS(J1001="M", "Medium", J1001="L", "Light", J1001="D", "Dark")} -> Medium | P1001: =_xlfn.XLOOKUP(Orders[[#This Row],[Customer ID]], customers!$A$2:$A$1001, customers!$I$2:$I$1001, 0) -> Yes

Sheet customers
A1: Customer ID | B1: Customer Name | C1: Email | D1: Phone Number | E1: Address Line 1 | F1: City | G1: Country | H1: Postcode | I1: Loyalty Card
A2: 17670-51384-MA | B2: Aloisia Allner | C2: aallner0@lulu.com | D2: +1 (862) 817-0124 | E2: 57999 Pepper Wood Alley | F2: Paterson | G2: United States | H2: 7505 | I2: Yes
A3: 73342-18763-UW | B3: Piotr Bote | C3: pbote1@yelp.com | D3: +353 (913) 396-4653 | E3: 2112 Ridgeway Hill | F3: Crumlin | G3: Ireland | H3: D6W | I3: No
A4: 21125-22134-PX | B4: Jami Redholes | C4: jredholes2@tmall.com | D4: +1 (210) 986-6806 | E4: 5214 Bartillon Park | F4: San Antonio | G4: United States | H4: 78205 | I4: Yes
A5: 71253-00052-RN | B5: Dene Azema | C5: dazema3@facebook.com | D5: +1 (217) 418-0714 | E5: 27 Maywood Place | F5: Springfield | G5: United States | H5: 62711 | I5: Yes
A6: 23806-46781-OU | B6: Christoffer O' Shea | D6: +353 (698) 362-9201 | E6: 38980 Manitowish Junction | F6: Cill Airne | G6: Ireland | H6: N41 | I6: No
A7: 86561-91660-RB | B7: Beryle Cottier | D7: +1 (570) 289-7473 | E7: 2651 Stoughton Place | F7: Scranton | G7: United States | H7: 18505 | I7: No
A8: 65223-29612-CB | B8: Shaylynn Lobe | C8: slobe6@nifty.com | D8: +1 (937) 954-4541 | E8: 7005 Mariners Cove Place | F8: Dayton | G8: United States | H8: 45440 | I8: Yes
A9: 21134-81676-FR | B9: Melvin Wharfe | D9: +353 (507) 574-3034 | E9: 7 Straubel Road | F9: Kill | G9: Ireland | H9: P24 | I9: Yes
A10: 03396-68805-ZC | B10: Guthrey Petracci | C10: gpetracci8@livejournal.com | D10: +1 (310) 868-1842 | E10: 949 Paget Parkway | F10: Los Angeles | G10: United States | H10: 90045 | I10: No
A11: 61021-27840-ZN | B11: Rodger Raven | C11: rraven9@ed.gov | D11: +1 (213) 263-0288 | E11: 1 Reinke Avenue | F11: Los Angeles | G11: United States | H11: 90065 | I11: No
A12: 76239-90137-UQ | B12: Ferrell Ferber | C12: fferbera@businesswire.com | D12: +1 (408) 383-5302 | E12: 68 High Crossing Court | F12: San Jose | G12: United States | H12: 95160 | I12: No
A13: 49315-21985-BB | B13: Duky Phizackerly | C13: dphizackerlyb@utexas.edu | D13: +1 (408) 533-6012 | E13: 28643 Bluejay Crossing | F13: San Jose | G13: United States | H13: 95194 | I13: Yes
A14: 34136-36674-OM | B14: Rosaleen Scholar | C14: rscholarc@nyu.edu | D14: +1 (804) 420-0420 | E14: 80915 Montana Park | F14: Richmond | G14: United States | H14: 23285 | I14: No
A15: 39396-12890-PE | B15: Terence Vanyutin | C15: tvanyutind@wix.com | E15: 331 Bunting Hill | F15: Migrate | G15: United States | H15: 41905 | I15: No
A16: 95875-73336-RG | B16: Patrice Trobe | C16: ptrobee@wunderground.com | D16: +1 (314) 240-7896 | E16: 827 Declaration Plaza | F16: Saint Louis | G16: United States | H16: 63131 | I16: Yes
A17: 25473-43727-BY | B17: Llywellyn Oscroft | C17: loscroftf@ebay.co.uk | E17: 022 Roth Place | F17: Philadelphia | G17: United States | H17: 19172 | I17: No
A18: 99643-51048-IQ | B18: Minni Alabaster | C18: malabasterg@hexun.com | D18: +1 (971) 483-6255 | E18: 3 Charing Cross Trail | F18: Portland | G18: United States | H18: 97271 | I18: No
A19: 62173-15287-CU | B19: Rhianon Broxup | C19: rbroxuph@jimdo.com | D19: +1 (713) 663-1338 | E19: 83517 Thierer Court | F19: Houston | G19: United States | H19: 77240 | I19: No
A20: 57611-05522-ST | B20: Pall Redford | C20: predfordi@ow.ly | E20: 7337 Hayes Junction | F20: Caherconlish | G20: Ireland | H20: F45 | I20: Yes
A21: 76664-37050-DT | B21: Aurea Corradino | C21: acorradinoj@harvard.edu | D21: +1 (646) 202-5965 | E21: 698 Canary Terrace | F21: New York City | G21: United States | H21: 10060 | I21: Yes
A22: 84565-53984-SX | B22: Kendal Scardefield | D22: +353 (733) 405-3302 | E22: 3 Northridge Crossing | F22: Clondalkin | G22: Ireland | H22: D24 | I22: Yes
A23: 03090-88267-BQ | B23: Avrit Davidowsky | C23: adavidowskyl@netvibes.com | D23: +1 (616) 481-9962 | E23: 9 Warrior Junction | F23: Grand Rapids | G23: United States | H23: 49560 | I23: No
A24: 37651-47492-NC | B24: Annabel Antuk | C24: aantukm@kickstarter.com | D24: +1 (941) 740-6268 | E24: 77965 Lawn Park | F24: Punta Gorda | G24: United States | H24: 33982 | I24: Yes
A25: 95399-57205-HI | B25: Iorgo Kleinert | C25: ikleinertn@timesonline.co.uk | D25: +1 (360) 352-6598 | E25: 1 Morningstar Lane | F25: Vancouver | G25: United States | H25: 98682 | I25: Yes
A26: 24010-66714-HW | B26: Chrisy Blofeld | C26: cblofeldo@amazon.co.uk | D26: +1 (303) 936-3357 | E26: 013 Talisman Terrace | F26: Englewood | G26: United States | H26: 80150 | I26: No
A27: 07591-92789-UA | B27: Culley Farris | D27: +1 (941) 267-4822 | E27: 4 Mitchell Drive | F27: Punta Gorda | G27: United States | H27: 33982 | I27: Yes
A28: 49231-44455-IC | B28: Selene Shales | C28: sshalesq@umich.edu | D28: +1 (707) 881-5004 | E28: 74 Bultman Plaza | F28: Petaluma | G28: United States | H28: 94975 | I28: Yes
A29: 50124-88608-EO | B29: Vivie Danneil | C29: vdanneilr@mtv.com | D29: +353 (751) 346-0399 | E29: 5626 Darwin Avenue | F29: Tralee | G29: Ireland | H29: V92 | I29: No
A30: 00888-74814-UZ | B30: Theresita Newbury | C30: tnewburys@usda.gov | D30: +353 (803) 587-0026 | E30: 79526 Bultman Lane | F30: Clonskeagh | G30: Ireland | H30: D04 | I30: No
A31: 14158-30713-OB | B31: Mozelle Calcutt | C31: mcalcuttt@baidu.com | D31: +353 (928) 869-1762 | E31: 4389 Russell Way | F31: Rathwire | G31: Ireland | H31: Y25 | I31: Yes
A32: 51427-89175-QJ | B32: Adrian Swaine | D32: +1 (303) 486-9517 | E32: 95 Straubel Hill | F32: Aurora | G32: United States | H32: 80044 | I32: No
A33: 52082-49024-ON | B33: Ray Leivesley | C33: rleivesleyv@canalblog.com | D33: +1 (212) 535-7791 | E33: 91 Stephen Drive | F33: Jamaica | G33: United States | H33: 11407 | I33: No
A34: 04540-43685-DV | B34: Nelly Basezzi | C34: nbasezziw@webeden.co.uk | D34: +353 (125) 815-7345 | E34: 923 Mallard Junction | F34: Bailieborough | G34: Ireland | H34: C15 | I34: Yes
A35: 39123-12846-YJ | B35: Gallard Gatheral | C35: ggatheralx@123-reg.co.uk | E35: 40 Clemons Place | F35: Grand Forks | G35: United States | H35: 58207 | I35: No
A36: 44981-99666-XB | B36: Una Welberry | C36: uwelberryy@ebay.co.uk | D36: +44 (392) 503-8132 | E36: 40915 Schlimgen Park | F36: Upton | G36: United Kingdom | H36: DN21 | I36: Yes
A37: 24825-51803-CQ | B37: Faber Eilhart | C37: feilhartz@who.int | D37: +1 (304) 510-6095 | E37: 6966 Victoria Street | F37: Charleston | G37: United States | H37: 25362 | I37: No
A38: 77634-13918-GJ | B38: Zorina Ponting | C38: zponting10@altervista.org | D38: +1 (501) 172-1476 | E38: 7118 Holmberg Court | F38: Little Rock | G38: United States | H38: 72204 | I38: No
A39: 13694-25001-LX | B39: Silvio Strase | C39: sstrase11@booking.com | D39: +1 (303) 579-8015 | E39: 5 Forest Lane | F39: Denver | G39: United States | H39: 80291 | I39: No
A40: 08523-01791-TI | B40: Dorie de la Tremoille | C40: dde12@unesco.org | D40: +1 (612) 492-5160 | E40: 0817 Dennis Street | F40: Minneapolis | G40: United States | H40: 55458 | I40: No
...

Sheet products
A1: Product ID | B1: Coffee Type | C1: Roast Type | D1: Size | E1: Unit Price | F1: Price per 100g | G1: Profit
A2: A-L-0.2 | B2: Ara | C2: L | D2: 0.2 | E2: 3.885 | F2: 1.9425 | G2: 0.34965
A3: A-L-0.5 | B3: Ara | C3: L | D3: 0.5 | E3: 7.77 | F3: 1.554 | G3: 0.6993
A4: A-L-1 | B4: Ara | C4: L | D4: 1 | E4: 12.95 | F4: 1.295 | G4: 1.1655
A5: A-L-2.5 | B5: Ara | C5: L | D5: 2.5 | E5: 29.785 | F5: 1.1914 | G5: 2.68065
A6: A-M-0.2 | B6: Ara | C6: M | D6: 0.2 | E6: 3.375 | F6: 1.6875 | G6: 0.30375
A7: A-M-0.5 | B7: Ara | C7: M | D7: 0.5 | E7: 6.75 | F7: 1.35 | G7: 0.6075
A8: A-M-1 | B8: Ara | C8: M | D8: 1 | E8: 11.25 | F8: 1.125 | G8: 1.0125
A9: A-M-2.5 | B9: Ara | C9: M | D9: 2.5 | E9: 25.875 | F9: 1.035 | G9: 2.32875
A10: A-D-0.2 | B10: Ara | C10: D | D10: 0.2 | E10: 2.985 | F10: 1.4925 | G10: 0.26865
A11: A-D-0.5 | B11: Ara | C11: D | D11: 0.5 | E11: 5.97 | F11: 1.194 | G11: 0.5373
A12: A-D-1 | B12: Ara | C12: D | D12: 1 | E12: 9.95 | F12: 0.995 | G12: 0.8955
A13: A-D-2.5 | B13: Ara | C13: D | D13: 2.5 | E13: 22.885 | F13: 0.9154 | G13: 2.05965
... A49: E-D-2.5 | B49: Exc | C49: D | D49: 2.5 | E49: 27.945 | F49: 1.1178 | G49: 3.07395
